Workbook
Name Slicer_Category: #N/A
Name Slicer_Order_Month: #N/A

Sheet Raw_Data
A1: Order_ID | B1: Order_Date | C1: Customer_ID | D1: Customer_Name | E1: City | F1: Product_ID | G1: Product_Name | H1: Category | I1: Quantity | J1: Unit_Price | K1: Total_Amount | L1: Payment_Method | M1: Payment_Status | N1: Order_Status | O1: Expected_Delivery_Date | P1: Actual_Delivery_Date | Q1: Delivery_Partner | R1: Return_Reason | S1: Cancellation_Reason
A2: ORD001 | B2: 46295 | C2: C007 | D2: Suresh | E2: Tenkasi | F2: P018 | G2: Office File | H2: Stationery | I2: 2 | J2: 120 | K2: 240 | L2: Debit Card | M2: Pending | N2: Delivered | O2: 46300 | P2: 46301 | Q2: Ecom Express
A3: ORD002 | B3: 46235 | C3: C017 | D3: Vijay | E3: Erode | F3: P015 | G3: Cookware Set | H3: Home & Kitchen | I3: 1 | J3: 3200 | K3: 3200 | L3: Debit Card | M3: Failed | N3: Cancelled | O3: 46239 | Q3: BlueDart | S3: Delivery delay
A4: ORD003 | B4: 46204 | C4: C018 | D4: Harini | E4: Coimbatore | F4: P008 | G4: Laptop Stand | H4: Electronics | I4: 2 | J4: 1100 | K4: 2200 | L4: UPI | M4: Pending | N4: Delivered | O4: 46207 | P4: 46209 | Q4: Delhivery
A5: ORD004 | B5: 46213 | C5: C003 | D5: Rahul | E5: Coimbatore | F5: P002 | G5: Keyboard | H5: Electronics | I5: 3 | J5: 850 | K5: 2550 | L5: Debit Card | M5: Paid | N5: Returned | O5: 46220 | P5: 46220 | Q5: Ecom Express | R5: Wrong product
A6: ORD005 | B6: 46235 | C6: C018 | D6: Harini | E6: Coimbatore | F6: P005 | G6: USB Cable | H6: Electronics | I6: 4 | J6: 350 | K6: 1400 | L6: Credit Card | M6: Paid | N6: Delivered | O6: 46241 | P6: 46244 | Q6: BlueDart
A7: ORD006 | B7: 46258 | C7: C004 | D7: Divya | E7: Trichy | F7: P014 | G7: Water Bottle | H7: Home & Kitchen | I7: 3 | J7: 500 | K7: 1500 | L7: UPI | M7: Paid | N7: Shipped | O7: 46264 | Q7: BlueDart
A8: ORD007 | B8: 46217 | C8: C002 | D8: Priya | E8: Madurai | F8: P013 | G8: Bedsheet | H8: Home & Kitchen | I8: 3 | J8: 950 | K8: 2850 | L8: Net Banking | M8: Paid | N8: Delivered | O8: 46221 | P8: 46221 | Q8: Ecom Express
A9: ORD008 | B9: 46239 | C9: C005 | D9: Karthik | E9: chennai | F9: P014 | G9: Water Bottle | H9: Home & Kitchen | I9: 2 | J9: 500 | K9: 1000 | L9: Cash on Delivery | M9: Paid | N9: Delivered | O9: 46245 | P9: 46245 | Q9: BlueDart
A10: ORD009 | B10: 46215 | C10: C002 | D10: Priya | E10: Madurai | F10: P018 | G10: Office File | H10: Stationery | I10: 1 | J10: 120 | K10: 120 | L10: Cash on Delivery | M10: Paid | N10: Delivered | O10: 46219 | P10: 46219 | Q10: Ecom Express
A11: ORD010 | B11: 46225 | C11: C007 | D11: Suresh | E11: Tenkasi | F11: P013 | G11: Bedsheet | H11: Home & Kitchen | I11: 1 | J11: 950 | K11: 950 | L11: Debit Card | M11: Paid | N11: Delivered | O11: 46231 | P11: 46230 | Q11: Ecom Express
A12: ORD011 | B12: 46223 | C12: C010 | D12: Asha | E12: Madurai | F12: P014 | G12: Water Bottle | H12: Home & Kitchen | I12: 4 | J12: 500 | K12: 2000 | L12: Credit Card | M12: Paid | N12: Shipped | O12: 46227 | Q12: BlueDart
A13: ORD012 | B13: 46244 | C13: C019 | D13: Prakash | E13: Salem | F13: P018 | G13: Office File | H13: Stationery | I13: 1 | J13: 120 | K13: 120 | L13: Net Banking | M13: Paid | N13: Placed | O13: 46247 | Q13: Ecom Express
A14: ORD013 | B14: 46211 | C14: C017 | D14: Vijay | E14: Erode | F14: P017 | G14: Notebook | H14: Stationery | I14: 2 | J14: 180 | K14: 360 | L14: Credit Card | M14: Paid | N14: Shipped | O14: 46218 | Q14: BlueDart
A15: ORD014 | B15: 46255 | C15: C020 | D15: Fathima | E15: Tirunelveli | F15: P003 | G15: Bluetooth Speaker | H15: Electronics | I15: 2 | J15: 1450 | K15: 2900 | L15: Net Banking | M15: Paid | N15: Delivered | O15: 46258 | P15: 46259 | Q15: BlueDart
A16: ORD015 | B16: 46288 | C16: C020 | D16: Fathima | E16: Tirunelveli | F16: P003 | G16: Bluetooth Speaker | H16: Electronics | I16: 4 | J16: 1450 | K16: 5800 | L16: Net Banking | M16: Pending | N16: Confirmed | O16: 46295 | Q16: DTDC
A17: ORD016 | B17: 46234 | C17: C009 | D17: Vignesh | E17: Chennai | F17: P007 | G17: Smart Watch | H17: Electronics | I17: 3 | J17: 2500 | K17: 7500 | L17: Credit Card | M17: Paid | N17: Placed | O17: 46239 | Q17: DTDC
A18: ORD017 | B18: 46205 | C18: C015 | D18: Santhosh | E18: Chennai | F18: P011 | G18: Backpack | H18: Fashion | I18: 1 | J18: 1250 | K18: 1250 | L18: UPI | M18: Pending | N18: Delivered | O18: 46211 | P18: 46212 | Q18: BlueDart
A19: ORD018 | B19: 46220 | C19: C018 | D19: Harini | E19: Coimbatore | F19: P007 | G19: Smart Watch | H19: Electronics | I19: 3 | J19: 2500 | K19: 7500 | L19: Credit Card | M19: Paid | N19: Shipped | O19: 46225 | Q19: DTDC
A20: ORD019 | B20: 46273 | C20: C010 | D20: Asha | E20: Madurai | F20: P006 | G20: Power Bank | H20: Electronics | I20: 4 | J20: 1200 | K20: 4800 | L20: Net Banking | M20: Pending | N20: Delivered | O20: 46278 | P20: 46279 | Q20: BlueDart
A21: ORD020 | B21: 46221 | C21: C018 | D21: Harini | E21: Coimbatore | F21: P010 | G21: Jeans | H21: Fashion | I21: 1 | J21: 1400 | K21: 1400 | L21: Net Banking | M21: Paid | N21: Delivered | O21: 46226 | P21: 46225 | Q21: Delhivery
A22: ORD021 | B22: 46295 | C22: C009 | D22: Vignesh | E22: Chennai | F22: P010 | G22: Jeans | H22: Fashion | I22: 2 | J22: 1400 | K22: 2800 | L22: Debit Card | M22: Paid | N22: Confirmed | O22: 46300 | Q22: Ecom Express
A23: ORD022 | B23: 46285 | C23: C009 | D23: Vignesh | E23: Chennai | F23: P002 | G23: Keyboard | H23: Electronics | I23: 1 | J23: 850 | K23: 850 | L23: UPI | M23: Paid | N23: delivered | O23: 46291 | P23: 46294 | Q23: BlueDart
A24: ORD023 | B24: 46224 | C24: C011 | D24: Manoj | E24: Coimbatore | F24: P005 | G24: USB Cable | H24: Electronics | I24: 3 | J24: 350 | K24: 1050 | L24: Cash on Delivery | M24: Pending | N24: Delivered | O24: 46230 | P24: 46231 | Q24: BlueDart
A25: ORD024 | B25: 46273 | C25: C004 | D25: Divya | E25: Trichy | F25: P003 | G25: Bluetooth Speaker | H25: Electronics | I25: 2 | J25: 1450 | K25: 2900 | L25: Net Banking | M25: Paid | N25: Shipped | O25: 46276 | Q25: Delhivery
A26: ORD025 | B26: 46243 | C26: C014 | D26: Lavanya | E26: Tenkasi | F26: P005 | G26: USB Cable | H26: Electronics | I26: 1 | J26: 350 | K26: 350 | L26: Debit Card | M26: Failed | N26: Cancelled | O26: 46248 | Q26: Delhivery | S26: Payment issue
A27: ORD026 | B27: 46283 | C27: C004 | D27: Divya | E27: Trichy | F27: P012 | G27: Sports Shoes | H27: Fashion | I27: 4 | J27: 2200 | K27: 8800 | L27: Credit Card | M27: Paid | N27: Confirmed | O27: 46287 | Q27: Delhivery
A28: ORD027 | B28: 46246 | C28: C014 | D28: Lavanya | E28: Tenkasi | F28: P001 | G28: Wireless Mouse | H28: Electronics | I28: 2 | J28: 650 | K28: 1300 | L28: Credit Card | M28: Pending | N28: Delivered | O28: 46252 | P28: 46255 | Q28: DTDC
A29: ORD028 | B29: 46208 | C29: C006 | D29: Meena | E29: Tirunelveli | F29: P004 | G29: Headphones | H29: Electronics | I29: 4 | J29: 1800 | K29: 7200 | L29: Cash on Delivery | M29: Paid | N29: Delivered | O29: 46214 | P29: 46214 | Q29: DTDC
A30: ORD029 | B30: 46207 | C30: C010 | D30: Asha | E30: Madurai | F30: P008 | G30: Laptop Stand | H30: Electronics | I30: 2 | J30: 1100 | K30: 2200 | L30: Debit Card | M30: Paid | N30: Delivered | O30: 46211 | P30: 46212 | Q30: BlueDart
A31: ORD030 | B31: 46290 | C31: C009 | D31: Vignesh | E31: Chennai | F31: P012 | G31: Sports Shoes | H31: Fashion | I31: 4 | J31: 2200 | K31: 8800 | L31: UPI | M31: Paid | N31: Returned | O31: 46297 | P31: 46297 | Q31: BlueDart | R31: Product not as expected
A32: ORD031 | B32: 46208 | C32: C006 | D32: Meena | E32: Tirunelveli | F32: P019 | G32: Desk Organizer | H32: Stationery | I32: 3 | J32: 450 | K32: 1350 | L32: Debit Card | M32: Paid | N32: Delivered | O32: 46211 | P32: 46212 | Q32: DTDC
A33: ORD032 | B33: 46253 | C33: C014 | D33: Lavanya | E33: Tenkasi | F33: P020 | G33: Calculator | H33: Stationery | I33: 1 | J33: 550 | K33: 550 | L33: Debit Card | M33: Paid | N33: Shipped | O33: 46260 | Q33: BlueDart
A34: ORD033 | B34: 46250 | C34: C014 | D34: Lavanya | E34: Tenkasi | F34: P001 | G34: Wireless Mouse | H34: Electronics | I34: 2 | J34: 650 | K34: 1300 | L34: Debit Card | M34: Pending | N34: Delivered | O34: 46256 | P34: 46255 | Q34: DTDC
A35: ORD034 | B35: 46289 | C35: C004 | D35: Divya | E35: Trichy | F35: P010 | G35: Jeans | H35: Fashion | I35: 3 | J35: 1400 | K35: 4200 | L35: Debit Card | M35: Paid | N35: Delivered | O35: 46295 | P35: 46295 | Q35: Delhivery
A36: ORD035 | B36: 46290 | C36: C007 | D36: Suresh | E36: Tenkasi | F36: P014 | G36: Water Bottle | H36: Home & Kitchen | I36: 4 | J36: 500 | K36: 2000 | L36: Net Banking | M36: Pending | N36: Out for Delivery | O36: 46294 | Q36: DTDC
A37: ORD036 | B37: 46242 | C37: C013 | D37: Dinesh | E37: Tirunelveli | F37: P018 | G37: Office File | H37: Stationery | I37: 1 | J37: 120 | K37: 120 | L37: Net Banking | M37: Paid | N37: Delivered | O37: 46247 | P37: 46247 | Q37: DTDC
A38: ORD037 | B38: 46290 | C38: C015 | D38: Santhosh | E38: Chennai | F38: P015 | G38: Cookware Set | H38: Home & Kitchen | I38: 4 | J38: 3200 | K38: 12800 | L38: Credit Card | M38: Paid | N38: Delivered | O38: 46294 | P38: 46295 | Q38: BlueDart
A39: ORD038 | B39: 46215 | C39: C010 | D39: Asha | E39: Madurai | F39: P017 | G39: Notebook | H39: Stationery | I39: 3 | J39: 180 | K39: 540 | L39: Debit Card | M39: Paid | N39: Returned | O39: 46219 | P39: 46221 | Q39: Delhivery | R39: Wrong product
A40: ORD039 | B40: 46235 | C40: C005 | D40: Karthik | E40: Salem | F40: P001 | G40: Wireless Mouse | H40: Electronics | I40: 1 | J40: 650 | K40: 650 | L40: Cash on Delivery | M40: Paid | N40: Delivered | O40: 46241 | P40: 46242 | Q40: Ecom Express
...

Sheet Cleaned_Data
A1: Order_ID | B1: Order_Date | C1: Customer_ID | D1: Customer_Name | E1: City | F1: Product_ID | G1: Product_Name | H1: Category | I1: Quantity | J1: Unit_Price | K1: Total_Amount | L1: Payment_Method | M1: Payment_Status | N1: Order_Status | O1: Expected_Delivery_Date | P1: Actual_Delivery_Date | Q1: Delivery_Partner | R1: Return_Reason | S1: Cancellation_Reason | T1: Delivery_Delay_Days | U1: Delivery_Performance | V1: Order Month
A2: ORD001 | B2: 46295 | C2: C007 | D2: Suresh | E2: Tenkasi | F2: P018 | G2: Office File | H2: Stationery | I2: 2 | J2: 120 | K2: 240 | L2: Debit Card | M2: Pending | N2: Delivered | O2: 46300 | P2: 46301 | Q2: Ecom Express | T2: =IF(P2="","",P2-O2) -> 1 | U2: =IF(T2="","Not Delivered",IF(T2<=0,"On Time",IF(T2<=2,"Slightly Delayed","Delayed"))) -> Slightly Delayed | V2: =TEXT(B2,"mmmm") -> September
A3: ORD002 | B3: 46235 | C3: C017 | D3: Vijay | E3: Erode | F3: P015 | G3: Cookware Set | H3: Home & Kitchen | I3: 1 | J3: 3200 | K3: 3200 | L3: Debit Card | M3: Failed | N3: Cancelled | O3: 46239 | Q3: BlueDart | S3: Delivery delay | T3: =IF(P3="","",P3-O3) | U3: =IF(T3="","Not Delivered",IF(T3<=0,"On Time",IF(T3<=2,"Slightly Delayed","Delayed"))) -> Not Delivered | V3: =TEXT(B3,"mmmm") -> August
A4: ORD003 | B4: 46204 | C4: C018 | D4: Harini | E4: Coimbatore | F4: P008 | G4: Laptop Stand | H4: Electronics | I4: 2 | J4: 1100 | K4: 2200 | L4: UPI | M4: Pending | N4: Delivered | O4: 46207 | P4: 46209 | Q4: Delhivery | T4: =IF(P4="","",P4-O4) -> 2 | U4: =IF(T4="","Not Delivered",IF(T4<=0,"On Time",IF(T4<=2,"Slightly Delayed","Delayed"))) -> Slightly Delayed | V4: =TEXT(B4,"mmmm") -> July
A5: ORD004 | B5: 46213 | C5: C003 | D5: Rahul | E5: Coimbatore | F5: P002 | G5: Keyboard | H5: Electronics | I5: 3 | J5: 850 | K5: 2550 | L5: Debit Card | M5: Paid | N5: Returned | O5: 46220 | P5: 46220 | Q5: Ecom Express | R5: Wrong product | T5: =IF(P5="","",P5-O5) -> 0 | U5: =IF(T5="","Not Delivered",IF(T5<=0,"On Time",IF(T5<=2,"Slightly Delayed","Delayed"))) -> On Time | V5: =TEXT(B5,"mmmm") -> July
A6: ORD005 | B6: 46235 | C6: C018 | D6: Harini | E6: Coimbatore | F6: P005 | G6: USB Cable | H6: Electronics | I6: 4 | J6: 350 | K6: 1400 | L6: Credit Card | M6: Paid | N6: Delivered | O6: 46241 | P6: 46244 | Q6: BlueDart | T6: =IF(P6="","",P6-O6) -> 3 | U6: =IF(T6="","Not Delivered",IF(T6<=0,"On Time",IF(T6<=2,"Slightly Delayed","Delayed"))) -> Delayed | V6: =TEXT(B6,"mmmm") -> August
A7: ORD006 | B7: 46258 | C7: C004 | D7: Divya | E7: Trichy | F7: P014 | G7: Water Bottle | H7: Home & Kitchen | I7: 3 | J7: 500 | K7: 1500 | L7: UPI | M7: Paid | N7: Shipped | O7: 46264 | Q7: BlueDart | T7: =IF(P7="","",P7-O7) | U7: =IF(T7="","Not Delivered",IF(T7<=0,"On Time",IF(T7<=2,"Slightly Delayed","Delayed"))) -> Not Delivered | V7: =TEXT(B7,"mmmm") -> August
A8: ORD007 | B8: 46217 | C8: C002 | D8: Priya | E8: Madurai | F8: P013 | G8: Bedsheet | H8: Home & Kitchen | I8: 3 | J8: 950 | K8: 2850 | L8: Net Banking | M8: Paid | N8: Delivered | O8: 46221 | P8: 46221 | Q8: Ecom Express | T8: =IF(P8="","",P8-O8) -> 0 | U8: =IF(T8="","Not Delivered",IF(T8<=0,"On Time",IF(T8<=2,"Slightly Delayed","Delayed"))) -> On Time | V8: =TEXT(B8,"mmmm") -> July
A9: ORD008 | B9: 46239 | C9: C005 | D9: Karthik | E9: Chennai | F9: P014 | G9: Water Bottle | H9: Home & Kitchen | I9: 2 | J9: 500 | K9: 1000 | L9: Cash on Delivery | M9: Paid | N9: Delivered | O9: 46245 | P9: 46245 | Q9: BlueDart | T9: =IF(P9="","",P9-O9) -> 0 | U9: =IF(T9="","Not Delivered",IF(T9<=0,"On Time",IF(T9<=2,"Slightly Delayed","Delayed"))) -> On Time | V9: =TEXT(B9,"mmmm") -> August
A10: ORD009 | B10: 46215 | C10: C002 | D10: Priya | E10: Madurai | F10: P018 | G10: Office File | H10: Stationery | I10: 1 | J10: 120 | K10: 120 | L10: Cash on Delivery | M10: Paid | N10: Delivered | O10: 46219 | P10: 46219 | Q10: Ecom Express | T10: =IF(P10="","",P10-O10) -> 0 | U10: =IF(T10="","Not Delivered",IF(T10<=0,"On Time",IF(T10<=2,"Slightly Delayed","Delayed"))) -> On Time | V10: =TEXT(B10,"mmmm") -> July
A11: ORD010 | B11: 46225 | C11: C007 | D11: Suresh | E11: Tenkasi | F11: P013 | G11: Bedsheet | H11: Home & Kitchen | I11: 1 | J11: 950 | K11: 950 | L11: Debit Card | M11: Paid | N11: Delivered | O11: 46231 | P11: 46230 | Q11: Ecom Express | T11: =IF(P11="","",P11-O11) -> -1 | U11: =IF(T11="","Not Delivered",IF(T11<=0,"On Time",IF(T11<=2,"Slightly Delayed","Delayed"))) -> On Time | V11: =TEXT(B11,"mmmm") -> July
A12: ORD011 | B12: 46223 | C12: C010 | D12: Asha | E12: Madurai | F12: P014 | G12: Water Bottle | H12: Home & Kitchen | I12: 4 | J12: 500 | K12: 2000 | L12: Credit Card | M12: Paid | N12: Shipped | O12: 46227 | Q12: BlueDart | T12: =IF(P12="","",P12-O12) | U12: =IF(T12="","Not Delivered",IF(T12<=0,"On Time",IF(T12<=2,"Slightly Delayed","Delayed"))) -> Not Delivered | V12: =TEXT(B12,"mmmm") -> July
A13: ORD012 | B13: 46244 | C13: C019 | D13: Prakash | E13: Salem | F13: P018 | G13: Office File | H13: Stationery | I13: 1 | J13: 120 | K13: 120 | L13: Net Banking | M13: Paid | N13: Placed | O13: 46247 | Q13: Ecom Express | T13: =IF(P13="","",P13-O13) | U13: =IF(T13="","Not Delivered",IF(T13<=0,"On Time",IF(T13<=2,"Slightly Delayed","Delayed"))) -> Not Delivered | V13: =TEXT(B13,"mmmm") -> August
A14: ORD013 | B14: 46211 | C14: C017 | D14: Vijay | E14: Erode | F14: P017 | G14: Notebook | H14: Stationery | I14: 2 | J14: 180 | K14: 360 | L14: Credit Card | M14: Paid | N14: Shipped | O14: 46218 | Q14: BlueDart | T14: =IF(P14="","",P14-O14) | U14: =IF(T14="","Not Delivered",IF(T14<=0,"On Time",IF(T14<=2,"Slightly Delayed","Delayed"))) -> Not Delivered | V14: =TEXT(B14,"mmmm") -> July
A15: ORD014 | B15: 46255 | C15: C020 | D15: Fathima | E15: Tirunelveli | F15: P003 | G15: Bluetooth Speaker | H15: Electronics | I15: 2 | J15: 1450 | K15: 2900 | L15: Net Banking | M15: Paid | N15: Delivered | O15: 46258 | P15: 46259 | Q15: BlueDart | T15: =IF(P15="","",P15-O15) -> 1 | U15: =IF(T15="","Not Delivered",IF(T15<=0,"On Time",IF(T15<=2,"Slightly Delayed","Delayed"))) -> Slightly Delayed | V15: =TEXT(B15,"mmmm") -> August
A16: ORD015 | B16: 46288 | C16: C020 | D16: Fathima | E16: Tirunelveli | F16: P003 | G16: Bluetooth Speaker | H16: Electronics | I16: 4 | J16: 1450 | K16: 5800 | L16: Net Banking | M16: Pending | N16: Confirmed | O16: 46295 | Q16: DTDC | T16: =IF(P16="","",P16-O16) | U16: =IF(T16="","Not Delivered",IF(T16<=0,"On Time",IF(T16<=2,"Slightly Delayed","Delayed"))) -> Not Delivered | V16: =TEXT(B16,"mmmm") -> September
A17: ORD016 | B17: 46234 | C17: C009 | D17: Vignesh | E17: Chennai | F17: P007 | G17: Smart Watch | H17: Electronics | I17: 3 | J17: 2500 | K17: 7500 | L17: Credit Card | M17: Paid | N17: Placed | O17: 46239 | Q17: DTDC | T17: =IF(P17="","",P17-O17) | U17: =IF(T17="","Not Delivered",IF(T17<=0,"On Time",IF(T17<=2,"Slightly Delayed","Delayed"))) -> Not Delivered | V17: =TEXT(B17,"mmmm") -> July
A18: ORD017 | B18: 46205 | C18: C015 | D18: Santhosh | E18: Chennai | F18: P011 | G18: Backpack | H18: Fashion | I18: 1 | J18: 1250 | K18: 1250 | L18: UPI | M18: Pending | N18: Delivered | O18: 46211 | P18: 46212 | Q18: BlueDart | T18: =IF(P18="","",P18-O18) -> 1 | U18: =IF(T18="","Not Delivered",IF(T18<=0,"On Time",IF(T18<=2,"Slightly Delayed","Delayed"))) -> Slightly Delayed | V18: =TEXT(B18,"mmmm") -> July
A19: ORD018 | B19: 46220 | C19: C018 | D19: Harini | E19: Coimbatore | F19: P007 | G19: Smart Watch | H19: Electronics | I19: 3 | J19: 2500 | K19: 7500 | L19: Credit Card | M19: Paid | N19: Shipped | O19: 46225 | Q19: DTDC | T19: =IF(P19="","",P19-O19) | U19: =IF(T19="","Not Delivered",IF(T19<=0,"On Time",IF(T19<=2,"Slightly Delayed","Delayed"))) -> Not Delivered | V19: =TEXT(B19,"mmmm") -> July
A20: ORD019 | B20: 46273 | C20: C010 | D20: Asha | E20: Madurai | F20: P006 | G20: Power Bank | H20: Electronics | I20: 4 | J20: 1200 | K20: 4800 | L20: Net Banking | M20: Pending | N20: Delivered | O20: 46278 | P20: 46279 | Q20: BlueDart | T20: =IF(P20="","",P20-O20) -> 1 | U20: =IF(T20="","Not Delivered",IF(T20<=0,"On Time",IF(T20<=2,"Slightly Delayed","Delayed"))) -> Slightly Delayed | V20: =TEXT(B20,"mmmm") -> September
A21: ORD020 | B21: 46221 | C21: C018 | D21: Harini | E21: Coimbatore | F21: P010 | G21: Jeans | H21: Fashion | I21: 1 | J21: 1400 | K21: 1400 | L21: Net Banking | M21: Paid | N21: Delivered | O21: 46226 | P21: 46225 | Q21: Delhivery | T21: =IF(P21="","",P21-O21) -> -1 | U21: =IF(T21="","Not Delivered",IF(T21<=0,"On Time",IF(T21<=2,"Slightly Delayed","Delayed"))) -> On Time | V21: =TEXT(B21,"mmmm") -> July
A22: ORD021 | B22: 46295 | C22: C009 | D22: Vignesh | E22: Chennai | F22: P010 | G22: Jeans | H22: Fashion | I22: 2 | J22: 1400 | K22: 2800 | L22: Debit Card | M22: Paid | N22: Confirmed | O22: 46300 | Q22: Ecom Express | T22: =IF(P22="","",P22-O22) | U22: =IF(T22="","Not Delivered",IF(T22<=0,"On Time",IF(T22<=2,"Slightly Delayed","Delayed"))) -> Not Delivered | V22: =TEXT(B22,"mmmm") -> September
A23: ORD022 | B23: 46285 | C23: C009 | D23: Vignesh | E23: Chennai | F23: P002 | G23: Keyboard | H23: Electronics | I23: 1 | J23: 850 | K23: 850 | L23: UPI | M23: Paid | N23: Delivered | O23: 46291 | P23: 46294 | Q23: BlueDart | T23: =IF(P23="","",P23-O23) -> 3 | U23: =IF(T23="","Not Delivered",IF(T23<=0,"On Time",IF(T23<=2,"Slightly Delayed","Delayed"))) -> Delayed | V23: =TEXT(B23,"mmmm") -> September
A24: ORD023 | B24: 46224 | C24: C011 | D24: Manoj | E24: Coimbatore | F24: P005 | G24: USB Cable | H24: Electronics | I24: 3 | J24: 350 | K24: 1050 | L24: Cash on Delivery | M24: Pending | N24: Delivered | O24: 46230 | P24: 46231 | Q24: BlueDart | T24: =IF(P24="","",P24-O24) -> 1 | U24: =IF(T24="","Not Delivered",IF(T24<=0,"On Time",IF(T24<=2,"Slightly Delayed","Delayed"))) -> Slightly Delayed | V24: =TEXT(B24,"mmmm") -> July
A25: ORD024 | B25: 46273 | C25: C004 | D25: Divya | E25: Trichy | F25: P003 | G25: Bluetooth Speaker | H25: Electronics | I25: 2 | J25: 1450 | K25: 2900 | L25: Net Banking | M25: Paid | N25: Shipped | O25: 46276 | Q25: Delhivery | T25: =IF(P25="","",P25-O25) | U25: =IF(T25="","Not Delivered",IF(T25<=0,"On Time",IF(T25<=2,"Slightly Delayed","Delayed"))) -> Not Delivered | V25: =TEXT(B25,"mmmm") -> September
A26: ORD025 | B26: 46243 | C26: C014 | D26: Lavanya | E26: Tenkasi | F26: P005 | G26: USB Cable | H26: Electronics | I26: 1 | J26: 350 | K26: 350 | L26: Debit Card | M26: Failed | N26: Cancelled | O26: 46248 | Q26: Delhivery | S26: Payment issue | T26: =IF(P26="","",P26-O26) | U26: =IF(T26="","Not Delivered",IF(T26<=0,"On Time",IF(T26<=2,"Slightly Delayed","Delayed"))) -> Not Delivered | V26: =TEXT(B26,"mmmm") -> August
A27: ORD026 | B27: 46283 | C27: C004 | D27: Divya | E27: Trichy | F27: P012 | G27: Sports Shoes | H27: Fashion | I27: 4 | J27: 2200 | K27: 8800 | L27: Credit Card | M27: Paid | N27: Confirmed | O27: 46287 | Q27: Delhivery | T27: =IF(P27="","",P27-O27) | U27: =IF(T27="","Not Delivered",IF(T27<=0,"On Time",IF(T27<=2,"Slightly Delayed","Delayed"))) -> Not Delivered | V27: =TEXT(B27,"mmmm") -> September
A28: ORD027 | B28: 46246 | C28: C014 | D28: Lavanya | E28: Tenkasi | F28: P001 | G28: Wireless Mouse | H28: Electronics | I28: 2 | J28: 650 | K28: 1300 | L28: Credit Card | M28: Pending | N28: Delivered | O28: 46252 | P28: 46255 | Q28: DTDC | T28: =IF(P28="","",P28-O28) -> 3 | U28: =IF(T28="","Not Delivered",IF(T28<=0,"On Time",IF(T28<=2,"Slightly Delayed","Delayed"))) -> Delayed | V28: =TEXT(B28,"mmmm") -> August
A29: ORD028 | B29: 46208 | C29: C006 | D29: Meena | E29: Tirunelveli | F29: P004 | G29: Headphones | H29: Electronics | I29: 4 | J29: 1800 | K29: 7200 | L29: Cash on Delivery | M29: Paid | N29: Delivered | O29: 46214 | P29: 46214 | Q29: DTDC | T29: =IF(P29="","",P29-O29) -> 0 | U29: =IF(T29="","Not Delivered",IF(T29<=0,"On Time",IF(T29<=2,"Slightly Delayed","Delayed"))) -> On Time | V29: =TEXT(B29,"mmmm") -> July
A30: ORD029 | B30: 46207 | C30: C010 | D30: Asha | E30: Madurai | F30: P008 | G30: Laptop Stand | H30: Electronics | I30: 2 | J30: 1100 | K30: 2200 | L30: Debit Card | M30: Paid | N30: Delivered | O30: 46211 | P30: 46212 | Q30: BlueDart | T30: =IF(P30="","",P30-O30) -> 1 | U30: =IF(T30="","Not Delivered",IF(T30<=0,"On Time",IF(T30<=2,"Slightly Delayed","Delayed"))) -> Slightly Delayed | V30: =TEXT(B30,"mmmm") -> July
A31: ORD030 | B31: 46290 | C31: C009 | D31: Vignesh | E31: Chennai | F31: P012 | G31: Sports Shoes | H31: Fashion | I31: 4 | J31: 2200 | K31: 8800 | L31: UPI | M31: Paid | N31: Returned | O31: 46297 | P31: 46297 | Q31: BlueDart | R31: Product not as expected | T31: =IF(P31="","",P31-O31) -> 0 | U31: =IF(T31="","Not Delivered",IF(T31<=0,"On Time",IF(T31<=2,"Slightly Delayed","Delayed"))) -> On Time | V31: =TEXT(B31,"mmmm") -> September
A32: ORD031 | B32: 46208 | C32: C006 | D32: Meena | E32: Tirunelveli | F32: P019 | G32: Desk Organizer | H32: Stationery | I32: 3 | J32: 450 | K32: 1350 | L32: Debit Card | M32: Paid | N32: Delivered | O32: 46211 | P32: 46212 | Q32: DTDC | T32: =IF(P32="","",P32-O32) -> 1 | U32: =IF(T32="","Not Delivered",IF(T32<=0,"On Time",IF(T32<=2,"Slightly Delayed","Delayed"))) -> Slightly Delayed | V32: =TEXT(B32,"mmmm") -> July
A33: ORD032 | B33: 46253 | C33: C014 | D33: Lavanya | E33: Tenkasi | F33: P020 | G33: Calculator | H33: Stationery | I33: 1 | J33: 550 | K33: 550 | L33: Debit Card | M33: Paid | N33: Shipped | O33: 46260 | Q33: BlueDart | T33: =IF(P33="","",P33-O33) | U33: =IF(T33="","Not Delivered",IF(T33<=0,"On Time",IF(T33<=2,"Slightly Delayed","Delayed"))) -> Not Delivered | V33: =TEXT(B33,"mmmm") -> August
A34: ORD033 | B34: 46250 | C34: C014 | D34: Lavanya | E34: Tenkasi | F34: P001 | G34: Wireless Mouse | H34: Electronics | I34: 2 | J34: 650 | K34: 1300 | L34: Debit Card | M34: Pending | N34: Delivered | O34: 46256 | P34: 46255 | Q34: DTDC | T34: =IF(P34="","",P34-O34) -> -1 | U34: =IF(T34="","Not Delivered",IF(T34<=0,"On Time",IF(T34<=2,"Slightly Delayed","Delayed"))) -> On Time | V34: =TEXT(B34,"mmmm") -> August
A35: ORD034 | B35: 46289 | C35: C004 | D35: Divya | E35: Trichy | F35: P010 | G35: Jeans | H35: Fashion | I35: 3 | J35: 1400 | K35: 4200 | L35: Debit Card | M35: Paid | N35: Delivered | O35: 46295 | P35: 46295 | Q35: Delhivery | T35: =IF(P35="","",P35-O35) -> 0 | U35: =IF(T35="","Not Delivered",IF(T35<=0,"On Time",IF(T35<=2,"Slightly Delayed","Delayed"))) -> On Time | V35: =TEXT(B35,"mmmm") -> September
A36: ORD035 | B36: 46290 | C36: C007 | D36: Suresh | E36: Tenkasi | F36: P014 | G36: Water Bottle | H36: Home & Kitchen | I36: 4 | J36: 500 | K36: 2000 | L36: Net Banking | M36: Pending | N36: Out for Delivery | O36: 46294 | Q36: DTDC | T36: =IF(P36="","",P36-O36) | U36: =IF(T36="","Not Delivered",IF(T36<=0,"On Time",IF(T36<=2,"Slightly Delayed","Delayed"))) -> Not Delivered | V36: =TEXT(B36,"mmmm") -> September
A37: ORD036 | B37: 46242 | C37: C013 | D37: Dinesh | E37: Tirunelveli | F37: P018 | G37: Office File | H37: Stationery | I37: 1 | J37: 120 | K37: 120 | L37: Net Banking | M37: Paid | N37: Delivered | O37: 46247 | P37: 46247 | Q37: DTDC | T37: =IF(P37="","",P37-O37) -> 0 | U37: =IF(T37="","Not Delivered",IF(T37<=0,"On Time",IF(T37<=2,"Slightly Delayed","Delayed"))) -> On Time | V37: =TEXT(B37,"mmmm") -> August
A38: ORD037 | B38: 46290 | C38: C015 | D38: Santhosh | E38: Chennai | F38: P015 | G38: Cookware Set | H38: Home & Kitchen | I38: 4 | J38: 3200 | K38: 12800 | L38: Credit Card | M38: Paid | N38: Delivered | O38: 46294 | P38: 46295 | Q38: BlueDart | T38: =IF(P38="","",P38-O38) -> 1 | U38: =IF(T38="","Not Delivered",IF(T38<=0,"On Time",IF(T38<=2,"Slightly Delayed","Delayed"))) -> Slightly Delayed | V38: =TEXT(B38,"mmmm") -> September
A39: ORD038 | B39: 46215 | C39: C010 | D39: Asha | E39: Madurai | F39: P017 | G39: Notebook | H39: Stationery | I39: 3 | J39: 180 | K39: 540 | L39: Debit Card | M39: Paid | N39: Returned | O39: 46219 | P39: 46221 | Q39: Delhivery | R39: Wrong product | T39: =IF(P39="","",P39-O39) -> 2 | U39: =IF(T39="","Not Delivered",IF(T39<=0,"On Time",IF(T39<=2,"Slightly Delayed","Delayed"))) -> Slightly Delayed | V39: =TEXT(B39,"mmmm") -> July
A40: ORD039 | B40: 46235 | C40: C005 | D40: Karthik | E40: Salem | F40: P001 | G40: Wireless Mouse | H40: Electronics | I40: 1 | J40: 650 | K40: 650 | L40: Cash on Delivery | M40: Paid | N40: Delivered | O40: 46241 | P40: 46242 | Q40: Ecom Express | T40: =IF(P40="","",P40-O40) -> 1 | U40: =IF(T40="","Not Delivered",IF(T40<=0,"On Time",IF(T40<=2,"Slightly Delayed","Delayed"))) -> Slightly Delayed | V40: =TEXT(B40,"mmmm") -> August
...

Sheet pivot category_sales
A3: Row Labels | B3: Sum of Total_Amount
A4: Electronics | B4: 254750
A5: Fashion | B5: 178550
A6: Home & Kitchen | B6: 150450
A7: Stationery | B7: 25970
A8: Grand Total | B8: 609720

Sheet Pivot City_wise_order
A3: Row Labels | B3: Count of Order_ID
A4: Chennai | B4: 29
A5: Coimbatore | B5: 31
A6: Erode | B6: 16
A7: Salem | B7: 28
A8: Tenkasi | B8: 20
A9: Tirunelveli | B9: 30
A10: Trichy | B10: 15
A11: Madurai | B11: 31
A12: Grand Total | B12: 200

Sheet Pivot payment_analysis
A3: Row Labels | B3: Count of Order_ID
A4: Cash on Delivery | B4: 46
A5: Credit Card | B5: 35
A6: Debit Card | B6: 49
A7: Net Banking | B7: 32
A8: UPI | B8: 38
A9: Grand Total | B9: 200

Sheet Pivot Delivery_Analysis
A3: Row Labels | B3: Count of Order_ID
A4: Delayed | B4: 13
A5: Not Delivered | B5: 72
A6: On Time | B6: 58
A7: Slightly Delayed | B7: 57
A8: Grand Total | B8: 200

Sheet Pivot_Order_Status
A3: Row Labels | B3: Count of Order_ID
A4: Cancelled | B4: 15
A5: Confirmed | B5: 10
A6: Delivered | B6: 115
A7: Out for Delivery | B7: 15
A8: Placed | B8: 8
A9: Returned | B9: 12
A10: Shipped | B10: 25
A11: Grand Total | B11: 200

Sheet Pivot_Reasons
A3: Row Labels | B3: Count of Order_ID | D3: Row Labels | E3: Count of Order_ID
A4: Damaged product | B4: 3 | D4: Customer changed mind | E4: 2
A5: Product not as expected | B5: 4 | D5: Delivery delay | E5: 4
A6: Size issue | B6: 2 | D6: Duplicate order | E6: 3
A7: Wrong product | B7: 3 | D7: Payment issue | E7: 3
A8: Grand Total | B8: 12 | D8: Product unavailable | E8: 3
D9: Grand Total | E9: 15

Sheet pivot monthly revenue
A3: Row Labels | B3: Sum of Total_Amount
A4: July | B4: 196730
A5: August | B5: 166000
A6: September | B6: 246990
A7: Grand Total | B7: 609720

Sheet Analysis
A1: Metric | B1: Value
A2: Total Orders | B2: =COUNTA(Cleaned_Data!A2:A201) -> 200
A3: Total Revenue | B3: =SUM(Cleaned_Data!K2:K201) -> 609720
A4: Delivered Orders | B4: =COUNTIF(Cleaned_Data!N2:N201,"Delivered") -> 115
A5: Cancelled Orders | B5: =COUNTIF(Cleaned_Data!N2:N201,"Cancelled") -> 15
A6: Returned Orders | B6: =COUNTIF(Cleaned_Data!N2:N201,"Returned") -> 12
A7: Average Delay (Days) | B7: =AVERAGE(Cleaned_Data!T2:T201) -> 0.703125
A8: Cancellation Rate | B8: =B5/B2 -> 0.075
A9: Returned Rate | B9: =B6/B2 -> 0.06
A10: Delivered % | B10: =B4/B2 -> 0.575
A11: On-Time Delivery | B11: =COUNTIF(Cleaned_Data!U2:U201,"On Time")/COUNT(Cleaned_Data!T2:T201) -> 0.453125

Sheet Dashboard
A1: SALES & DELIVERY ANALYTICS DASHBOARD
